<?xml version="1.0"?>
<robot xmlns:xacro="http://ros.org/xacro" name="rbot">

<xacro:arg name="type" default="rbot"/>

<xacro:include filename="inertial_macros.xacro"/>


  <!--COLOURS FOR THE THE LINKS-->

  <material name="blue">
    <color rgba="0 0 0.8 1"/>
  </material>
  <material name="black">
    <color rgba="0 0 0 1"/>
  </material>
  <material name="green">
    <color rgba="0.2 1 0.2 1"/>
  </material>
    <material name="red">
    <color rgba="1 0 0 1"/>
  </material>


  <!-- BASE LINK (EMPTY)-->
  <!-- REFERENCE TO THE WORLD-->
  
  <link name="base_link">
  
  </link>
  

  <!-- CHASSIS-->
    
  <link name="chassis">
    <visual>
        <origin xyz="0.15 0 0.075"/>
        <geometry>
            <box size="0.3 0.3 0.15"/>
        </geometry>
        <material name="blue"/>
    </visual>
    <collision>
        <origin xyz="0.15 0 0.075"/>
        <geometry>
            <box size="0.3 0.3 0.15"/>
        </geometry>
    </collision>
    <xacro:inertial_box mass="0.5" x="0.3" y="0.3" z="0.15">
        <origin xyz="0.15 0 0.075" rpy="0 0 0"/>
    </xacro:inertial_box>
  </link>

  <!-- GAZEBO COLOURS -->

  <gazebo reference="chassis">
      <material>Gazebo/Blue</material>
  </gazebo>

  <!-- CHASSIS JOINT -->

  <joint name="chassis_joint" type="fixed">
      <parent link="base_link"/>
      <child link="chassis"/>
      <origin xyz="-0.1 0 0"/>
  </joint>



  <!-- RIGHT WHEEL-->
 
  <link name="right_wheel">
    <visual>
      <geometry>
        <cylinder length="0.04" radius="0.05"/>
      </geometry>
 	    <material name="green"/>
    </visual>
    <collision>
      <geometry>
        <cylinder length="0.04" radius="0.05"/>
      </geometry>
    </collision>
    <xacro:inertial_cylinder mass="0.1" length="0.04" radius="0.05">
        <origin xyz="0 0 0" rpy="0 0 0"/>
    </xacro:inertial_cylinder>
  </link>

  <!-- GAZEBO COLOURS -->

  <gazebo reference="right_wheel">
      <material>Gazebo/Green</material>
  </gazebo>

  <!--RIGHT WHEEL JOINT-->
  <!-- WE USE PI/2 TO GET THE ROLL VALUE-->

  <joint name="right_wheel_joint" type="continuous">
    <parent link="base_link"/>
    <child link="right_wheel"/>
    <origin rpy="1.57075 0 0" xyz="0 -0.175 0"/>
    <axis xyz="0 0 -1"/>
  </joint>
 
  <!--LEFT WHEEL-->

  <link name="left_wheel">
    <visual>
      <geometry>
        <cylinder length="0.04" radius="0.05"/>
      </geometry>
 	    <material name="green"/>
    </visual>
    <collision>
      <geometry>
        <cylinder length="0.04" radius="0.05"/>
      </geometry>
    </collision>
    <xacro:inertial_cylinder mass="0.1" length="0.04" radius="0.05">
        <origin xyz="0 0 0" rpy="0 0 0"/>
    </xacro:inertial_cylinder>
  </link>

   <!-- GAZEBO COLOURS -->

  <gazebo reference="left_wheel">
      <material>Gazebo/Green</material>
  </gazebo>

  <!--LEFT WHEEL JOINT-->

  <joint name="left_wheel_joint" type="continuous">
    <parent link="base_link"/>
    <child link="left_wheel"/>
    <origin rpy="-1.57075 0 0" xyz="0 0.175 0"/>
    <axis xyz="0 0 1"/>
  </joint>

  <!--CASTER WHEEL-->

  <link name="caster_wheel">
    <visual>
      <geometry>
        <sphere radius="0.05"/>
      </geometry>
  	<material name="black"/>
    </visual>
    <collision>
      <geometry>
        <sphere radius="0.05"/>
      </geometry>
    </collision>
    <xacro:inertial_sphere mass="0.1" radius="0.05">
        <origin xyz="0 0 0" rpy="0 0 0"/>
    </xacro:inertial_sphere>
  </link>
  

  <!--CASTER WHEEL JOINT-->

  <joint name="caster_wheel_joint" type="fixed">
    <parent link="chassis"/>
    <child link="caster_wheel"/>
    <origin xyz="0.24 0 0"/>
  </joint>

  <!-- GAZEBO COLOURS -->
  <!-- SPECIFY THE FRICTION COEFFICENT FOR GAZEBO-->
  <gazebo reference="caster_wheel">
      <material>Gazebo/Black</material>
      <mu1 value ="0.01"/>
      <mu2 value ="0.01"/>
  </gazebo>

 <gazebo>
  <plugin
    filename="libignition-gazebo-diff-drive-system.so"
    name="ignition::gazebo::systems::DiffDrive">
    <left_joint>base_to_wheel2</left_joint>
    <right_joint>base_to_wheel1</right_joint>
    <wheel_separation>0.35</wheel_separation>
    <wheel_radius>0.05</wheel_radius>
    <odom_publish_frequency>0.1</odom_publish_frequency>
    <topic>cmd_vel</topic>
 </plugin>
 <!-- Moving Forward-->
 <plugin filename="libignition-gazebo-triggered-publisher-system.so"
        name="ignition::gazebo::systems::TriggeredPublisher">
    <input type="ignition.msgs.Int32" topic="/keyboard/keypress">
        <match field="data">16777235</match>
    </input>
    <output type="ignition.msgs.Twist" topic="/cmd_vel">
        linear: {x: 0.5}
    </output>
 </plugin>
 <!-- Moving Backward-->
 <plugin filename="libignition-gazebo-triggered-publisher-system.so"
        name="ignition::gazebo::systems::TriggeredPublisher">
    <input type="ignition.msgs.Int32" topic="/keyboard/keypress">
        <match field="data">16777237</match>
    </input>
    <output type="ignition.msgs.Twist" topic="/cmd_vel">
        linear: {x: -0.5}
    </output>
 </plugin>
 <!-- Moving Letf-->
 <plugin filename="libignition-gazebo-triggered-publisher-system.so"
        name="ignition::gazebo::systems::TriggeredPublisher">
    <input type="ignition.msgs.Int32" topic="/keyboard/keypress">
        <match field="data">16777237</match>
    </input>
    <output type="ignition.msgs.Twist" topic="/cmd_vel">
        angular: {z: 0.5}
    </output>
 </plugin>
<!-- Moving Right-->
 <plugin filename="libignition-gazebo-triggered-publisher-system.so"
        name="ignition::gazebo::systems::TriggeredPublisher">
    <input type="ignition.msgs.Int32" topic="/keyboard/keypress">
        <match field="data">16777237</match>
    </input>
    <output type="ignition.msgs.Twist" topic="/cmd_vel">
        angular: {z: -0.5}
    </output>
 </plugin>
 </gazebo>
</robot>

