<?xml version="1.0" ?>
<!-- =================================================================================== -->
<!-- |    This document was autogenerated by xacro from rbot.urdf.xacro                | -->
<!-- |    EDITING THIS FILE BY HAND IS NOT RECOMMENDED                                 | -->
<!-- =================================================================================== -->
<robot name="rbot">
  <!-- Specify some standard inertial calculations https://en.wikipedia.org/wiki/List_of_moments_of_inertia -->
  <!-- These make use of xacro's mathematical functionality -->
  <!--COLOURS FOR THE THE LINKS-->
  <material name="blue">
    <color rgba="0 0 0.8 1"/>
  </material>
  <material name="black">
    <color rgba="0 0 0 1"/>
  </material>
  <material name="green">
    <color rgba="0.2 1 0.2 1"/>
  </material>
  <material name="red">
    <color rgba="1 0 0 1"/>
  </material>
  
  
  <!-- BASE LINK (EMPTY)-->
  <!-- REFERENCE TO THE WORLD-->
  <link name="base_link">
  
  </link>



  
  <!-- CHASSIS-->
  <link name="chassis">
    <visual>
      <origin xyz="0.15 0 0.075"/>
      <geometry>
        <box size="0.3 0.3 0.15"/>
      </geometry>
      <material name="blue"/>
    </visual>
    <collision>
      <origin xyz="0.15 0 0.075"/>
      <geometry>
        <box size="0.3 0.3 0.15"/>
      </geometry>
    </collision>
    <inertial>
      <origin rpy="0 0 0" xyz="0.15 0 0.075"/>
      <mass value="0.5"/>
      <inertia ixx="0.00375" ixy="0.0" ixz="0.0" iyy="0.00375" iyz="0.0" izz="0.0075"/>
    </inertial>
  </link>
  
  <!-- GAZEBO -->
  <gazebo reference="chassis">
    <material>Gazebo/Blue</material>
    <!--IMU SENSOR-->
    <sensor name="imu_sensor" type="imu">
    <always_on>1</always_on>
    <update_rate>1</update_rate>
    <visualize>true</visualize>
    <topic>imu</topic>
    </sensor>
</gazebo>

  
  <!-- CHASSIS JOINT -->
  <joint name="chassis_joint" type="fixed">
    <parent link="base_link"/>
    <child link="chassis"/>
    <origin xyz="-0.1 0 0"/>
  </joint>
  
  <!-- RIGHT WHEEL-->
  <link name="right_wheel">
    <visual>
      <geometry>
        <cylinder length="0.04" radius="0.05"/>
      </geometry>
      <material name="green"/>
    </visual>
    <collision>
      <geometry>
        <cylinder length="0.04" radius="0.05"/>
      </geometry>
    </collision>
    <inertial>
      <origin rpy="0 0 0" xyz="0 0 0"/>
      <mass value="0.1"/>
      <inertia ixx="7.583333333333335e-05" ixy="0.0" ixz="0.0" iyy="7.583333333333335e-05" iyz="0.0" izz="0.00012500000000000003"/>
    </inertial>
  </link>
  
  <!-- GAZEBO -->
  <gazebo reference="right_wheel">
    <material>Gazebo/Green</material>
  </gazebo>
  
  <!--RIGHT WHEEL JOINT-->
  <joint name="right_wheel_joint" type="continuous">
    <parent link="base_link"/>
    <child link="right_wheel"/>
    <origin rpy="1.57075 0 0" xyz="0 -0.175 0"/>
    <axis xyz="0 0 -1"/>
  </joint>
  
  <!--LEFT WHEEL-->
  <link name="left_wheel">
    <visual>
      <geometry>
        <cylinder length="0.04" radius="0.05"/>
      </geometry>
      <material name="green"/>
    </visual>
    <collision>
      <geometry>
        <cylinder length="0.04" radius="0.05"/>
      </geometry>
    </collision>
    <inertial>
      <origin rpy="0 0 0" xyz="0 0 0"/>
      <mass value="0.1"/>
      <inertia ixx="7.583333333333335e-05" ixy="0.0" ixz="0.0" iyy="7.583333333333335e-05" iyz="0.0" izz="0.00012500000000000003"/>
    </inertial>
  </link>
  
  <!-- GAZEBO -->
  <gazebo reference="left_wheel">
    <material>Gazebo/Green</material>
  </gazebo>
  
  <!--LEFT WHEEL JOINT-->
  <joint name="left_wheel_joint" type="continuous">
    <parent link="base_link"/>
    <child link="left_wheel"/>
    <origin rpy="-1.57075 0 0" xyz="0 0.175 0"/>
    <axis xyz="0 0 1"/>
  </joint>
  
  <!--CASTER WHEEL-->
  <link name="caster_wheel">
    <visual>
      <geometry>
        <sphere radius="0.05"/>
      </geometry>
      <material name="black"/>
    </visual>
    <collision>
      <geometry>
        <sphere radius="0.05"/>
      </geometry>
    </collision>
    <inertial>
      <origin rpy="0 0 0" xyz="0 0 0"/>
      <mass value="0.5"/>
      <inertia ixx="0.0005" ixy="0" ixz="0" iyy="0.0005" iyz="0" izz="0.0005"/>
    </inertial>
  </link>
  
  <!--CASTER WHEEL JOINT-->
  <joint name="caster_wheel_joint" type="fixed">
    <parent link="chassis"/>
    <child link="caster_wheel"/>
    <origin xyz="0.24 0 0"/>
  </joint>
  
  
  <!-- SPECIFY THE FRICTION COEFFICENT FOR GAZEBO-->
  <gazebo reference="caster_wheel">
    <material>Gazebo/Black</material>
    <mu1 value="0.01"/>
    <mu2 value="0.01"/>
  </gazebo>
  <gazebo>

 						
 						
 						<!-- PLUGINS -->
 						
 						
  <!-- ros_control plugin -->
  <gazebo>
    <plugin filename="libgazebo_ros_control.so" name="gazebo_ros_control">
      <robotNamespace>/rbot</robotNamespace>
      <robotSimType>gazebo_ros_control/DefaultRobotHWSim</robotSimType>
    </plugin>
  </gazebo>
    
    
    
    <!--IMU SENSOR-->
    <plugin filename="libignition-gazebo-imu-system.so"
            name="ignition::gazebo::systems::Imu">
    </plugin>

    
  
    <plugin filename="libignition-gazebo-diff-drive-system.so" name="ignition::gazebo::systems::DiffDrive">
      <left_joint>left_wheel_joint</left_joint>
      <right_joint>right_wheel_joint</right_joint>
      <wheel_separation>0.35</wheel_separation>
      <wheel_radius>0.05</wheel_radius>
      <odom_publish_frequency>0.1</odom_publish_frequency>
      <topic>cmd_vel</topic>
    </plugin>
    
    
    
    <!-- Moving Forward-->
    <plugin filename="libignition-gazebo-triggered-publisher-system.so" name="ignition::gazebo::systems::TriggeredPublisher">
      <input topic="/keyboard/keypress" type="ignition.msgs.Int32">
        <match field="data">16777235</match>
      </input>
      <output topic="/cmd_vel" type="ignition.msgs.Twist">
        linear: {x: 0.5}, angular: {z: 0.0}
    </output>
    </plugin>
    
    
    
    <!-- Moving Backward-->
    <plugin filename="libignition-gazebo-triggered-publisher-system.so" name="ignition::gazebo::systems::TriggeredPublisher">
      <input topic="/keyboard/keypress" type="ignition.msgs.Int32">
        <match field="data">16777237</match>
      </input>
      <output topic="/cmd_vel" type="ignition.msgs.Twist">
        linear: {x: -0.5}, angular: {z: 0.0}
    </output>
    </plugin>
    
    
    
    <!-- Rotating right-->
        <plugin filename="libignition-gazebo-triggered-publisher-system.so"
                name="ignition::gazebo::systems::TriggeredPublisher">
            <input type="ignition.msgs.Int32" topic="/keyboard/keypress">
                <match field="data">16777236</match>
            </input>
            <output type="ignition.msgs.Twist" topic="/cmd_vel">
                linear: {x: 0.0}, angular: {z: -0.5}
            </output>
        </plugin>
        
        
        

        <!--Rotating left-->
        <plugin filename="libignition-gazebo-triggered-publisher-system.so"
                name="ignition::gazebo::systems::TriggeredPublisher">
            <input type="ignition.msgs.Int32" topic="/keyboard/keypress">
                <match field="data">16777234</match>
            </input>
            <output type="ignition.msgs.Twist" topic="/cmd_vel">
                linear: {x: 0.0}, angular: {z: 0.5}
            </output>
        </plugin>
    
    
  </gazebo>
</robot>
